Workbook

Sheet overview
B1: Count | C1: Percent
A2: Total Model Change | B2: 1426
A3: Documented Model Change | B3: 541 | C3: =(B3/B2)*100 -> 37.938289
A4: Model Change with Rationale | B4: {=SUMPRODUCT( --('key information'!$J$2:$J$220=1), IFERROR(VALUE('key information'!$D$2:$D$220),0) )} -> 328 | C4: =(B4/B2)*100 -> 23.001403
A6: Total Documentation | B6: 417
A7: Document with Rationale | B7: =COUNT(_xlfn.UNIQUE('key information'!A2:A220)) -> 209 | C7: =B7/B6*100 -> 50.119904
A9: Code Count | B9: =COUNTA(_xlfn.UNIQUE(codes!A2:A71)) -> 70
A10: Sub-theme Count | B10: =COUNTA(_xlfn.UNIQUE('sub-themes'!A2:A21)) -> 20
A11: Theme Count | B11: =COUNTA(_xlfn.UNIQUE(themes!A2:A6)) -> 5
F13: Count | G13: Percent by Type | H13: Doc Coverage per Type | K13: Count | L13: Percent by Type | M13: Rationale Coverage per Type | N13: Rationale Coverage per Documented Type
A14: Total Model Change | B14: =B2 -> 1426 | E14: Documented Model Change | F14: =B3 -> 541 | J14: Model Change with Rationale | K14: =B4 -> 328
A15: Total Addition | B15: 1263 | C15: =(B15/$B$14)*100 -> 88.569425 | E15: Documented Addition | F15: 488 | G15: =(F15/$F$14)*100 -> 90.203327 | H15: =F15/B15*100 -> 38.638163 | J15: Addition with Rationale | K15: {=SUMPRODUCT( --('key information'!$J$2:$J$220=1), --('key information'!$F$2:$F$220="['add']"), IFERROR(VALUE('key information'!$D$2:$D$220),0) )} -> 284 | L15: =K15/$K$14*100 -> 86.585366 | M15: =K15/$B15*100 -> 22.486144 | N15: =K15/F15*100 -> 58.196721
A16: Total Removal | B16: 119 | C16: =(B16/$B$14)*100 -> 8.345021 | E16: Documented Removal | F16: 20 | G16: =(F16/$F$14)*100 -> 3.6968577 | H16: =F16/B16*100 -> 16.806723 | J16: Removal with Rationale | K16: {=SUMPRODUCT( --('key information'!$J$2:$J$220=1), --('key information'!$F$2:$F$220="['remove']"), IFERROR(VALUE('key information'!$D$2:$D$220),0) )} -> 15 | L16: =K16/$K$14*100 -> 4.5731707 | M16: =K16/$B16*100 -> 12.605042 | N16: =K16/F16*100 -> 75
A17: Total Migration | B17: 44 | C17: =(B17/$B$14)*100 -> 3.085554 | E17: Documented Migration | F17: 33 | G17: =(F17/$F$14)*100 -> 6.0998152 | H17: =F17/B17*100 -> 75 | J17: Migration with Rationale | K17: {=SUMPRODUCT( --('key information'!$J$2:$J$220=1), --('key information'!$F$2:$F$220="['migrate']"), IFERROR(VALUE('key information'!$D$2:$D$220),0) )} -> 29 | L17: =K17/$K$14*100 -> 8.8414634 | M17: =K17/$B17*100 -> 65.909091 | N17: =K17/F17*100 -> 87.878788
F19: Count | G19: Percent by Doc Type | H19: Rationale Coverage per Doc Type
A20: Total Document | B20: =B6 -> 417 | E20: Document with Rationale | F20: =B7 -> 209
A21: Commit with Document | B21: 172 | C21: =B21/$B$20*100 -> 41.247002 | E21: Commit with Rationale | F21: 74 | G21: =F21/$F$20*100 -> 35.406699 | H21: =F21/B21*100 -> 43.023256
A22: Pull Request with Document | B22: 121 | C22: =B22/$B$20*100 -> 29.016787 | E22: Pull Request with Rationale | F22: 65 | G22: =F22/$F$20*100 -> 31.100478 | H22: =F22/B22*100 -> 53.719008
A23: Release Note with Document | B23: 71 | C23: =B23/$B$20*100 -> 17.026379 | E23: Release Note with Rationale | F23: 34 | G23: =F23/$F$20*100 -> 16.267943 | H23: =F23/B23*100 -> 47.887324
A24: Other MD with Document | B24: 19 | C24: =B24/$B$20*100 -> 4.5563549 | E24: Other MD with Rationale | F24: 13 | G24: =F24/$F$20*100 -> 6.2200957 | H24: =F24/B24*100 -> 68.421053
A25: Issue with Document | B25: 19 | C25: =B25/$B$20*100 -> 4.5563549 | E25: Issue with Rationale | F25: 12 | G25: =F25/$F$20*100 -> 5.7416268 | H25: =F25/B25*100 -> 63.157895
A26: Code Comment with Document | B26: 15 | C26: =B26/$B$20*100 -> 3.5971223 | E26: Code Comment with Rationale | F26: 11 | G26: =F26/$F$20*100 -> 5.2631579 | H26: =F26/B26*100 -> 73.333333

Sheet key information
A1: Doc ID | B1: new seq | C1: doc type | D1: changed_model_event_count | E1: changed_model_unique_count | F1: evidence_role | G1: changed_model_name | H1: NormModels | I1: SeqKey | J1: FirstOccur | K1: CodeEventKey | L1: FirstOccur_Code | M1: SubthemeEventKey | N1: FirstOccur_Subtheme | O1: SubthemeEventKey | P1: FirstOccur_Subtheme | Q1: DocCodeKey | R1: FirstOccur_Doc | S1: DocSubthemeKey | T1: FirstOccur_Subtheme | U1: DocThemeKey | V1: FirstOccur_Theme | W1: Key information | X1: Code | Y1: Sub-Theme | Z1: Theme
A2: 1 | B2: 5 | C2: commit | D2: 2 | E2: 1 | F2: ['add'] | G2: ['snowflake/snowflake-arctic-embed-m-long'] | H2: =SUBSTITUTE(SUBSTITUTE(SUBSTITUTE(SUBSTITUTE(G2,"[",""),"]",""),"'",""),", ","|") -> snowflake/snowflake-arctic-embed-m-long | I2: =B2 & "||" & F2 & "||" & H2 -> 5||['add']||snowflake/snowflake-arctic-embed-m-long | J2: =IF(COUNTIF($I$2:I2, I2)=1, 1, 0) -> 1 | K2: =I2 & "||" & X2 -> 5||['add']||snowflake/snowflake-arctic-embed-m-long||C1 | L2: =IF(COUNTIF($K$2:K2, K2)=1, 1, 0) -> 1 | M2: =I2 & "||" & Y2 -> 5||['add']||snowflake/snowflake-arctic-embed-m-long||M13 | N2: =IF(COUNTIF($M$2:M2, M2)=1, 1, 0) -> 1 | O2: =I2 & "||" & Z2 -> 5||['add']||snowflake/snowflake-arctic-embed-m-long||T1 | P2: =IF(COUNTIF($O$2:O2, O2)=1, 1, 0) -> 1 | Q2: =A2& "||" & X2 -> 1||C1 | R2: =IF(COUNTIF($Q$2:Q2, Q2)=1, 1, 0) -> 1 | S2: =A2& "||" & Y2 -> 1||M13 | T2: =IF(COUNTIF($S$2:S2, S2)=1, 1, 0) -> 1 | U2: =A2& "||" & Z2 -> 1||T1 | V2: =IF(COUNTIF($U$2:U2, U2)=1, 1, 0) -> 1 | W2: Introduced an embedding model to enable model-based jailbreak detection. | X2: C1 | Y2: =_xlfn.XLOOKUP(X2, codes!A:A, codes!F:F, "") -> M13 | Z2: =_xlfn.XLOOKUP(Y2, 'sub-themes'!A:A, 'sub-themes'!H:H, "") -> T1
A3: 2 | B3: 5 | C3: other_doc | D3: 2 | E3: 1 | F3: ['add'] | G3: ['snowflake/snowflake-arctic-embed-m-long'] | H3: =SUBSTITUTE(SUBSTITUTE(SUBSTITUTE(SUBSTITUTE(G3,"[",""),"]",""),"'",""),", ","|") -> snowflake/snowflake-arctic-embed-m-long | I3: =B3 & "||" & F3 & "||" & H3 -> 5||['add']||snowflake/snowflake-arctic-embed-m-long | J3: =IF(COUNTIF($I$2:I3, I3)=1, 1, 0) -> 0 | K3: =I3 & "||" & X3 -> 5||['add']||snowflake/snowflake-arctic-embed-m-long||C1 | L3: =IF(COUNTIF($K$2:K3, K3)=1, 1, 0) -> 0 | M3: =I3 & "||" & Y3 -> 5||['add']||snowflake/snowflake-arctic-embed-m-long||M13 | N3: =IF(COUNTIF($M$2:M3, M3)=1, 1, 0) -> 0 | O3: =I3 & "||" & Z3 -> 5||['add']||snowflake/snowflake-arctic-embed-m-long||T1 | P3: =IF(COUNTIF($O$2:O3, O3)=1, 1, 0) -> 0 | Q3: =A3& "||" & X3 -> 2||C1 | R3: =IF(COUNTIF($Q$2:Q3, Q3)=1, 1, 0) -> 1 | S3: =A3& "||" & Y3 -> 2||M13 | T3: =IF(COUNTIF($S$2:S3, S3)=1, 1, 0) -> 1 | U3: =A3& "||" & Z3 -> 2||T1 | V3: =IF(COUNTIF($U$2:U3, U3)=1, 1, 0) -> 1 | W3: Adopted an embedding-based model to support machine-learning-driven jailbreak detection. | X3: C1 | Y3: =_xlfn.XLOOKUP(X3, codes!A:A, codes!F:F, "") -> M13 | Z3: =_xlfn.XLOOKUP(Y3, 'sub-themes'!A:A, 'sub-themes'!H:H, "") -> T1
A4: 3 | B4: 6 | C4: commit | D4: 2 | E4: 1 | F4: ['add'] | G4: ['openai-community/gpt2-large'] | H4: =SUBSTITUTE(SUBSTITUTE(SUBSTITUTE(SUBSTITUTE(G4,"[",""),"]",""),"'",""),", ","|") -> openai-community/gpt2-large | I4: =B4 & "||" & F4 & "||" & H4 -> 6||['add']||openai-community/gpt2-large | J4: =IF(COUNTIF($I$2:I4, I4)=1, 1, 0) -> 1 | K4: =I4 & "||" & X4 -> 6||['add']||openai-community/gpt2-large||C10 | L4: =IF(COUNTIF($K$2:K4, K4)=1, 1, 0) -> 1 | M4: =I4 & "||" & Y4 -> 6||['add']||openai-community/gpt2-large||M10 | N4: =IF(COUNTIF($M$2:M4, M4)=1, 1, 0) -> 1 | O4: =I4 & "||" & Z4 -> 6||['add']||openai-community/gpt2-large||T3 | P4: =IF(COUNTIF($O$2:O4, O4)=1, 1, 0) -> 1 | Q4: =A4& "||" & X4 -> 3||C10 | R4: =IF(COUNTIF($Q$2:Q4, Q4)=1, 1, 0) -> 1 | S4: =A4& "||" & Y4 -> 3||M10 | T4: =IF(COUNTIF($S$2:S4, S4)=1, 1, 0) -> 1 | U4: =A4& "||" & Z4 -> 3||T3 | V4: =IF(COUNTIF($U$2:U4, U4)=1, 1, 0) -> 1 | W4: A language model is added as an evaluation component to compute perplexity-based heuristics for jailbreak detection. | X4: C10 | Y4: =_xlfn.XLOOKUP(X4, codes!A:A, codes!F:F, "") -> M10 | Z4: =_xlfn.XLOOKUP(Y4, 'sub-themes'!A:A, 'sub-themes'!H:H, "") -> T3
A5: 4 | B5: 7 | C5: release_note | D5: 1 | E5: 1 | F5: ['add'] | G5: ['mahmoodlab/titan'] | H5: =SUBSTITUTE(SUBSTITUTE(SUBSTITUTE(SUBSTITUTE(G5,"[",""),"]",""),"'",""),", ","|") -> mahmoodlab/titan | I5: =B5 & "||" & F5 & "||" & H5 -> 7||['add']||mahmoodlab/titan | J5: =IF(COUNTIF($I$2:I5, I5)=1, 1, 0) -> 1 | K5: =I5 & "||" & X5 -> 7||['add']||mahmoodlab/titan||C2 | L5: =IF(COUNTIF($K$2:K5, K5)=1, 1, 0) -> 1 | M5: =I5 & "||" & Y5 -> 7||['add']||mahmoodlab/titan||M18 | N5: =IF(COUNTIF($M$2:M5, M5)=1, 1, 0) -> 1 | O5: =I5 & "||" & Z5 -> 7||['add']||mahmoodlab/titan||T2 | P5: =IF(COUNTIF($O$2:O5, O5)=1, 1, 0) -> 1 | Q5: =A5& "||" & X5 -> 4||C2 | R5: =IF(COUNTIF($Q$2:Q5, Q5)=1, 1, 0) -> 1 | S5: =A5& "||" & Y5 -> 4||M18 | T5: =IF(COUNTIF($S$2:S5, S5)=1, 1, 0) -> 1 | U5: =A5& "||" & Z5 -> 4||T2 | V5: =IF(COUNTIF($U$2:U5, U5)=1, 1, 0) -> 1 | W5: Added pretrained models to support additional feature extraction pipelines. | X5: C2 | Y5: =_xlfn.XLOOKUP(X5, codes!A:A, codes!F:F, "") -> M18 | Z5: =_xlfn.XLOOKUP(Y5, 'sub-themes'!A:A, 'sub-themes'!H:H, "") -> T2
A6: 5 | B6: 7 | C6: commit | D6: 1 | E6: 1 | F6: ['add'] | G6: ['mahmoodlab/titan'] | H6: =SUBSTITUTE(SUBSTITUTE(SUBSTITUTE(SUBSTITUTE(G6,"[",""),"]",""),"'",""),", ","|") -> mahmoodlab/titan | I6: =B6 & "||" & F6 & "||" & H6 -> 7||['add']||mahmoodlab/titan | J6: =IF(COUNTIF($I$2:I6, I6)=1, 1, 0) -> 0 | K6: =I6 & "||" & X6 -> 7||['add']||mahmoodlab/titan||C2 | L6: =IF(COUNTIF($K$2:K6, K6)=1, 1, 0) -> 0 | M6: =I6 & "||" & Y6 -> 7||['add']||mahmoodlab/titan||M18 | N6: =IF(COUNTIF($M$2:M6, M6)=1, 1, 0) -> 0 | O6: =I6 & "||" & Z6 -> 7||['add']||mahmoodlab/titan||T2 | P6: =IF(COUNTIF($O$2:O6, O6)=1, 1, 0) -> 0 | Q6: =A6& "||" & X6 -> 5||C2 | R6: =IF(COUNTIF($Q$2:Q6, Q6)=1, 1, 0) -> 1 | S6: =A6& "||" & Y6 -> 5||M18 | T6: =IF(COUNTIF($S$2:S6, S6)=1, 1, 0) -> 1 | U6: =A6& "||" & Z6 -> 5||T2 | V6: =IF(COUNTIF($U$2:U6, U6)=1, 1, 0) -> 1 | W6: There is currently one available model-based detection, using a random forest-based detector trained on [`snowflake/snowflake-arctic-embed-m-long`](https://huggingface.co/Snowflake/snowflake-arctic-embed-m-long) embeddings. | X6: C2 | Y6: =_xlfn.XLOOKUP(X6, codes!A:A, codes!F:F, "") -> M18 | Z6: =_xlfn.XLOOKUP(Y6, 'sub-themes'!A:A, 'sub-themes'!H:H, "") -> T2
A7: 6 | B7: 7 | C7: pull_request | D7: 1 | E7: 1 | F7: ['add'] | G7: ['mahmoodlab/titan'] | H7: =SUBSTITUTE(SUBSTITUTE(SUBSTITUTE(SUBSTITUTE(G7,"[",""),"]",""),"'",""),", ","|") -> mahmoodlab/titan | I7: =B7 & "||" & F7 & "||" & H7 -> 7||['add']||mahmoodlab/titan | J7: =IF(COUNTIF($I$2:I7, I7)=1, 1, 0) -> 0 | K7: =I7 & "||" & X7 -> 7||['add']||mahmoodlab/titan||C2 | L7: =IF(COUNTIF($K$2:K7, K7)=1, 1, 0) -> 0 | M7: =I7 & "||" & Y7 -> 7||['add']||mahmoodlab/titan||M18 | N7: =IF(COUNTIF($M$2:M7, M7)=1, 1, 0) -> 0 | O7: =I7 & "||" & Z7 -> 7||['add']||mahmoodlab/titan||T2 | P7: =IF(COUNTIF($O$2:O7, O7)=1, 1, 0) -> 0 | Q7: =A7& "||" & X7 -> 6||C2 | R7: =IF(COUNTIF($Q$2:Q7, Q7)=1, 1, 0) -> 1 | S7: =A7& "||" & Y7 -> 6||M18 | T7: =IF(COUNTIF($S$2:S7, S7)=1, 1, 0) -> 1 | U7: =A7& "||" & Z7 -> 6||T2 | V7: =IF(COUNTIF($U$2:U7, U7)=1, 1, 0) -> 1 | W7: Added pretrained models to support additional feature extraction pipelines. | X7: C2 | Y7: =_xlfn.XLOOKUP(X7, codes!A:A, codes!F:F, "") -> M18 | Z7: =_xlfn.XLOOKUP(Y7, 'sub-themes'!A:A, 'sub-themes'!H:H, "") -> T2
A8: 7 | B8: 12 | C8: release_note | D8: 1 | E8: 1 | F8: ['add'] | G8: ['google-bert/bert-base-cased'] | H8: =SUBSTITUTE(SUBSTITUTE(SUBSTITUTE(SUBSTITUTE(G8,"[",""),"]",""),"'",""),", ","|") -> google-bert/bert-base-cased | I8: =B8 & "||" & F8 & "||" & H8 -> 12||['add']||google-bert/bert-base-cased | J8: =IF(COUNTIF($I$2:I8, I8)=1, 1, 0) -> 1 | K8: =I8 & "||" & X8 -> 12||['add']||google-bert/bert-base-cased||C3 | L8: =IF(COUNTIF($K$2:K8, K8)=1, 1, 0) -> 1 | M8: =I8 & "||" & Y8 -> 12||['add']||google-bert/bert-base-cased||M19 | N8: =IF(COUNTIF($M$2:M8, M8)=1, 1, 0) -> 1 | O8: =I8 & "||" & Z8 -> 12||['add']||google-bert/bert-base-cased||T3 | P8: =IF(COUNTIF($O$2:O8, O8)=1, 1, 0) -> 1 | Q8: =A8& "||" & X8 -> 7||C3 | R8: =IF(COUNTIF($Q$2:Q8, Q8)=1, 1, 0) -> 1 | S8: =A8& "||" & Y8 -> 7||M19 | T8: =IF(COUNTIF($S$2:S8, S8)=1, 1, 0) -> 1 | U8: =A8& "||" & Z8 -> 7||T3 | V8: =IF(COUNTIF($U$2:U8, U8)=1, 1, 0) -> 1 | W8: Introduced an unsupervised context retriever using BERT to improve named entity recognition and downstream rule-based unification. | X8: C3 | Y8: =_xlfn.XLOOKUP(X8, codes!A:A, codes!F:F, "") -> M19 | Z8: =_xlfn.XLOOKUP(Y8, 'sub-themes'!A:A, 'sub-themes'!H:H, "") -> T3
A9: 8 | B9: 16 | C9: commit | D9: 1 | E9: 1 | F9: ['add'] | G9: ['google-bert/bert-base-uncased'] | H9: =SUBSTITUTE(SUBSTITUTE(SUBSTITUTE(SUBSTITUTE(G9,"[",""),"]",""),"'",""),", ","|") -> google-bert/bert-base-uncased | I9: =B9 & "||" & F9 & "||" & H9 -> 16||['add']||google-bert/bert-base-uncased | J9: =IF(COUNTIF($I$2:I9, I9)=1, 1, 0) -> 1 | K9: =I9 & "||" & X9 -> 16||['add']||google-bert/bert-base-uncased||C4 | L9: =IF(COUNTIF($K$2:K9, K9)=1, 1, 0) -> 1 | M9: =I9 & "||" & Y9 -> 16||['add']||google-bert/bert-base-uncased||M1 | N9: =IF(COUNTIF($M$2:M9, M9)=1, 1, 0) -> 1 | O9: =I9 & "||" & Z9 -> 16||['add']||google-bert/bert-base-uncased||T1 | P9: =IF(COUNTIF($O$2:O9, O9)=1, 1, 0) -> 1 | Q9: =A9& "||" & X9 -> 8||C4 | R9: =IF(COUNTIF($Q$2:Q9, Q9)=1, 1, 0) -> 1 | S9: =A9& "||" & Y9 -> 8||M1 | T9: =IF(COUNTIF($S$2:S9, S9)=1, 1, 0) -> 1 | U9: =A9& "||" & Z9 -> 8||T1 | V9: =IF(COUNTIF($U$2:U9, U9)=1, 1, 0) -> 1 | W9: More additions of models to rel extraction | X9: C4 | Y9: =_xlfn.XLOOKUP(X9, codes!A:A, codes!F:F, "") -> M1 | Z9: =_xlfn.XLOOKUP(Y9, 'sub-themes'!A:A, 'sub-themes'!H:H, "") -> T1
A10: 9 | B10: 16 | C10: pull_request | D10: 1 | E10: 1 | F10: ['add'] | G10: ['google-bert/bert-base-uncased'] | H10: =SUBSTITUTE(SUBSTITUTE(SUBSTITUTE(SUBSTITUTE(G10,"[",""),"]",""),"'",""),", ","|") -> google-bert/bert-base-uncased | I10: =B10 & "||" & F10 & "||" & H10 -> 16||['add']||google-bert/bert-base-uncased | J10: =IF(COUNTIF($I$2:I10, I10)=1, 1, 0) -> 0 | K10: =I10 & "||" & X10 -> 16||['add']||google-bert/bert-base-uncased||C4 | L10: =IF(COUNTIF($K$2:K10, K10)=1, 1, 0) -> 0 | M10: =I10 & "||" & Y10 -> 16||['add']||google-bert/bert-base-uncased||M1 | N10: =IF(COUNTIF($M$2:M10, M10)=1, 1, 0) -> 0 | O10: =I10 & "||" & Z10 -> 16||['add']||google-bert/bert-base-uncased||T1 | P10: =IF(COUNTIF($O$2:O10, O10)=1, 1, 0) -> 0 | Q10: =A10& "||" & X10 -> 9||C4 | R10: =IF(COUNTIF($Q$2:Q10, Q10)=1, 1, 0) -> 1 | S10: =A10& "||" & Y10 -> 9||M1 | T10: =IF(COUNTIF($S$2:S10, S10)=1, 1, 0) -> 1 | U10: =A10& "||" & Z10 -> 9||T1 | V10: =IF(COUNTIF($U$2:U10, U10)=1, 1, 0) -> 1 | W10: Add bert-base-uncased for Relation extraction | X10: C4 | Y10: =_xlfn.XLOOKUP(X10, codes!A:A, codes!F:F, "") -> M1 | Z10: =_xlfn.XLOOKUP(Y10, 'sub-themes'!A:A, 'sub-themes'!H:H, "") -> T1
A11: 10 | B11: 17 | C11: commit | D11: 1 | E11: 1 | F11: ['add'] | G11: ['prajjwal1/bert-tiny'] | H11: =SUBSTITUTE(SUBSTITUTE(SUBSTITUTE(SUBSTITUTE(G11,"[",""),"]",""),"'",""),", ","|") -> prajjwal1/bert-tiny | I11: =B11 & "||" & F11 & "||" & H11 -> 17||['add']||prajjwal1/bert-tiny | J11: =IF(COUNTIF($I$2:I11, I11)=1, 1, 0) -> 1 | K11: =I11 & "||" & X11 -> 17||['add']||prajjwal1/bert-tiny||C5 | L11: =IF(COUNTIF($K$2:K11, K11)=1, 1, 0) -> 1 | M11: =I11 & "||" & Y11 -> 17||['add']||prajjwal1/bert-tiny||M17 | N11: =IF(COUNTIF($M$2:M11, M11)=1, 1, 0) -> 1 | O11: =I11 & "||" & Z11 -> 17||['add']||prajjwal1/bert-tiny||T3 | P11: =IF(COUNTIF($O$2:O11, O11)=1, 1, 0) -> 1 | Q11: =A11& "||" & X11 -> 10||C5 | R11: =IF(COUNTIF($Q$2:Q11, Q11)=1, 1, 0) -> 1 | S11: =A11& "||" & Y11 -> 10||M17 | T11: =IF(COUNTIF($S$2:S11, S11)=1, 1, 0) -> 1 | U11: =A11& "||" & Z11 -> 10||T3 | V11: =IF(COUNTIF($U$2:U11, U11)=1, 1, 0) -> 1 | W11: Adding test case for BERT and reverting config changes | X11: C5 | Y11: =_xlfn.XLOOKUP(X11, codes!A:A, codes!F:F, "") -> M17 | Z11: =_xlfn.XLOOKUP(Y11, 'sub-themes'!A:A, 'sub-themes'!H:H, "") -> T3
A12: 11 | B12: 26 | C12: issue | D12: 1 | E12: 1 | F12: ['add'] | G12: ['google-bert/bert-base-uncased'] | H12: =SUBSTITUTE(SUBSTITUTE(SUBSTITUTE(SUBSTITUTE(G12,"[",""),"]",""),"'",""),", ","|") -> google-bert/bert-base-uncased | I12: =B12 & "||" & F12 & "||" & H12 -> 26||['add']||google-bert/bert-base-uncased | J12: =IF(COUNTIF($I$2:I12, I12)=1, 1, 0) -> 1 | K12: =I12 & "||" & X12 -> 26||['add']||google-bert/bert-base-uncased||C68 | L12: =IF(COUNTIF($K$2:K12, K12)=1, 1, 0) -> 1 | M12: =I12 & "||" & Y12 -> 26||['add']||google-bert/bert-base-uncased||M6 | N12: =IF(COUNTIF($M$2:M12, M12)=1, 1, 0) -> 1 | O12: =I12 & "||" & Z12 -> 26||['add']||google-bert/bert-base-uncased||T4 | P12: =IF(COUNTIF($O$2:O12, O12)=1, 1, 0) -> 1 | Q12: =A12& "||" & X12 -> 11||C68 | R12: =IF(COUNTIF($Q$2:Q12, Q12)=1, 1, 0) -> 1 | S12: =A12& "||" & Y12 -> 11||M6 | T12: =IF(COUNTIF($S$2:S12, S12)=1, 1, 0) -> 1 | U12: =A12& "||" & Z12 -> 11||T4 | V12: =IF(COUNTIF($U$2:U12, U12)=1, 1, 0) -> 1 | W12: Add a regression test using BERT to reproduce and guard against failures when loading/saving Transformers models that rely on remote/custom code (trust_remote_code=True) via MLflow’s Transformers integration. (triggered by changes or behavior in the upstream Transformers ecosystem) | X12: C68 | Y12: =_xlfn.XLOOKUP(X12, codes!A:A, codes!F:F, "") -> M6 | Z12: =_xlfn.XLOOKUP(Y12, 'sub-themes'!A:A, 'sub-themes'!H:H, "") -> T4
A13: 12 | B13: 27 | C13: pull_request | D13: 1 | E13: 1 | F13: ['migrate'] | G13: ['openai/whisper-tiny'] | H13: =SUBSTITUTE(SUBSTITUTE(SUBSTITUTE(SUBSTITUTE(G13,"[",""),"]",""),"'",""),", ","|") -> openai/whisper-tiny | I13: =B13 & "||" & F13 & "||" & H13 -> 27||['migrate']||openai/whisper-tiny | J13: =IF(COUNTIF($I$2:I13, I13)=1, 1, 0) -> 1 | K13: =I13 & "||" & X13 -> 27||['migrate']||openai/whisper-tiny||C7 | L13: =IF(COUNTIF($K$2:K13, K13)=1, 1, 0) -> 1 | M13: =I13 & "||" & Y13 -> 27||['migrate']||openai/whisper-tiny||M7 | N13: =IF(COUNTIF($M$2:M13, M13)=1, 1, 0) -> 1 | O13: =I13 & "||" & Z13 -> 27||['migrate']||openai/whisper-tiny||T5 | P13: =IF(COUNTIF($O$2:O13, O13)=1, 1, 0) -> 1 | Q13: =A13& "||" & X13 -> 12||C7 | R13: =IF(COUNTIF($Q$2:Q13, Q13)=1, 1, 0) -> 1 | S13: =A13& "||" & Y13 -> 12||M7 | T13: =IF(COUNTIF($S$2:S13, S13)=1, 1, 0) -> 1 | U13: =A13& "||" & Z13 -> 12||T5 | V13: =IF(COUNTIF($U$2:U13, U13)=1, 1, 0) -> 1 | W13: Replace whisper-small with whisper-tiny to save disk space | X13: C7 | Y13: =_xlfn.XLOOKUP(X13, codes!A:A, codes!F:F, "") -> M7 | Z13: =_xlfn.XLOOKUP(Y13, 'sub-themes'!A:A, 'sub-themes'!H:H, "") -> T5
... A63: 61 | B63: 99 | C63: other_doc | D63: 1 | E63: 1 | F63: ['migrate'] | G63: ['retrieva-jp/t5-small-short'] | H63: =SUBSTITUTE(SUBSTITUTE(SUBSTITUTE(SUBSTITUTE(G63,"[",""),"]",""),"'",""),", ","|") -> retrieva-jp/t5-small-short | I63: =B63 & "||" & F63 & "||" & H63 -> 99||['migrate']||retrieva-jp/t5-small-short | J63: =IF(COUNTIF($I$2:I63, I63)=1, 1, 0) -> 0 | K63: =I63 & "||" & X63 -> 99||['migrate']||retrieva-jp/t5-small-short||C7 | L63: =IF(COUNTIF($K$2:K63, K63)=1, 1, 0) -> 1 | M63: =I63 & "||" & Y63 -> 99||['migrate']||retrieva-jp/t5-small-short||M7 | N63: =IF(COUNTIF($M$2:M63, M63)=1, 1, 0) -> 1 | O63: =I63 & "||" & Z63 -> 99||['migrate']||retrieva-jp/t5-small-short||T5 | P63: =IF(COUNTIF($O$2:O63, O63)=1, 1, 0) -> 0 | Q63: =A63& "||" & X63 -> 61||C7 | R63: =IF(COUNTIF($Q$2:Q63, Q63)=1, 1, 0) -> 1 | S63: =A63& "||" & Y63 -> 61||M7 | T63: =IF(COUNTIF($S$2:S63, S63)=1, 1, 0) -> 1 | U63: =A63& "||" & Z63 -> 61||T5 | V63: =IF(COUNTIF($U$2:U63, U63)=1, 1, 0) -> 1 | W63: Replace mt5 models with small t5 models pre-trained on Japanese corpora in seq2seq module. | X63: C7 | Y63: =_xlfn.XLOOKUP(X63, codes!A:A, codes!F:F, "") -> M7 | Z63: =_xlfn.XLOOKUP(Y63, 'sub-themes'!A:A, 'sub-themes'!H:H, "") -> T5
A64: 62 | B64: 113 | C64: release_note | D64: 11 | E64: 11 | F64: ['add'] | G64: ['compvis/stable-diffusion-v1-4', 'stabilityai/stable-diffusion-2-1-base', 'stabilityai/stable-diffusion-2-base', 'dreamlike-art/dreamlike-photoreal-2.0', 'segmind/ssd-1b', 'dreamlike-art/dreamlike-diffusion-1.0', 'prompthero/openjourney', 'microsoft/promptist', 'nitrosocke/redshift-diffusion', 'aiml-tuda/stable-diffusion-safe', '22h/vintedois-diffusion-v0-1'] | H64: =SUBSTITUTE(SUBSTITUTE(SUBSTITUTE(SUBSTITUTE(G64,"[",""),"]",""),"'",""),", ","|") -> compvis/stable-diffusion-v1-4|stabilityai/stable-diffusion-2-1-base|stabilityai/stable-diffusion-2-base|dreamlike-art/dreamlike-photoreal-2.0|segmind/ssd-1b|dreamlike-art/dreamlike-diffusion-1.0|prompthero/openjourney|microsoft/promptist|nitrosocke/redshift-diffusion|aiml-tuda/stable-diffusion-safe|22h/vintedois-diffusion-v0-1 | I64: =B64&"||"&F64&"" -> 113||['add'] | J64: =IF(COUNTIF($I$2:I64, I64)=1, 1, 0) -> 1 | K64: =I64 & "||" & X64 -> 113||['add']||C31 | L64: =IF(COUNTIF($K$2:K64, K64)=1, 1, 0) -> 1 | M64: =I64 & "||" & Y64 -> 113||['add']||M4 | N64: =IF(COUNTIF($M$2:M64, M64)=1, 1, 0) -> 1 | O64: =I64 & "||" & Z64 -> 113||['add']||T1 | P64: =IF(COUNTIF($O$2:O64, O64)=1, 1, 0) -> 1 | Q64: =A64& "||" & X64 -> 62||C31 | R64: =IF(COUNTIF($Q$2:Q64, Q64)=1, 1, 0) -> 1 | S64: =A64& "||" & Y64 -> 62||M4 | T64: =IF(COUNTIF($S$2:S64, S64)=1, 1, 0) -> 1 | U64: =A64& "||" & Z64 -> 62||T1 | V64: =IF(COUNTIF($U$2:U64, U64)=1, 1, 0) -> 1 | W64: Added model to enable text-to-image generation. | X64: C31 | Y64: =_xlfn.XLOOKUP(X64, codes!A:A, codes!F:F, "") -> M4 | Z64: =_xlfn.XLOOKUP(Y64, 'sub-themes'!A:A, 'sub-themes'!H:H, "") -> T1
A65: 63 | B65: 114 | C65: code_comment | D65: 1 | E65: 1 | F65: ['add'] | G65: ['stabilityai/stable-diffusion-x4-upscaler'] | H65: =SUBSTITUTE(SUBSTITUTE(SUBSTITUTE(SUBSTITUTE(G65,"[",""),"]",""),"'",""),", ","|") -> stabilityai/stable-diffusion-x4-upscaler | I65: =B65 & "||" & F65 & "||" & H65 -> 114||['add']||stabilityai/stable-diffusion-x4-upscaler | J65: =IF(COUNTIF($I$2:I65, I65)=1, 1, 0) -> 1 | K65: =I65 & "||" & X65 -> 114||['add']||stabilityai/stable-diffusion-x4-upscaler||C31 | L65: =IF(COUNTIF($K$2:K65, K65)=1, 1, 0) -> 1 | M65: =I65 & "||" & Y65 -> 114||['add']||stabilityai/stable-diffusion-x4-upscaler||M4 | N65: =IF(COUNTIF($M$2:M65, M65)=1, 1, 0) -> 1 | O65: =I65 & "||" & Z65 -> 114||['add']||stabilityai/stable-diffusion-x4-upscaler||T1 | P65: =IF(COUNTIF($O$2:O65, O65)=1, 1, 0) -> 1 | Q65: =A65& "||" & X65 -> 63||C31 | R65: =IF(COUNTIF($Q$2:Q65, Q65)=1, 1, 0) -> 1 | S65: =A65& "||" & Y65 -> 63||M4 | T65: =IF(COUNTIF($S$2:S65, S65)=1, 1, 0) -> 1 | U65: =A65& "||" & Z65 -> 63||T1 | V65: =IF(COUNTIF($U$2:U65, U65)=1, 1, 0) -> 1 | W65: Added inference support for DeepFloyd-IF text-to-image models. | X65: C31 | Y65: =_xlfn.XLOOKUP(X65, codes!A:A, codes!F:F, "") -> M4 | Z65: =_xlfn.XLOOKUP(Y65, 'sub-themes'!A:A, 'sub-themes'!H:H, "") -> T1
A66: 64 | B66: 117 | C66: other_doc | D66: 2 | E66: 1 | F66: ['add'] | G66: ['distilbert/distilbert-base-uncased-finetuned-sst-2-english'] | H66: =SUBSTITUTE(SUBSTITUTE(SUBSTITUTE(SUBSTITUTE(G66,"[",""),"]",""),"'",""),", ","|") -> distilbert/distilbert-base-uncased-finetuned-sst-2-english | I66: =B66 & "||" & F66 & "||" & H66 -> 117||['add']||distilbert/distilbert-base-uncased-finetuned-sst-2-english | J66: =IF(COUNTIF($I$2:I66, I66)=1, 1, 0) -> 1 | K66: =I66 & "||" & X66 -> 117||['add']||distilbert/distilbert-base-uncased-finetuned-sst-2-english||C32 | L66: =IF(COUNTIF($K$2:K66, K66)=1, 1, 0) -> 1 | M66: =I66 & "||" & Y66 -> 117||['add']||distilbert/distilbert-base-uncased-finetuned-sst-2-english||M7 | N66: =IF(COUNTIF($M$2:M66, M66)=1, 1, 0) -> 1 | O66: =I66 & "||" & Z66 -> 117||['add']||distilbert/distilbert-base-uncased-finetuned-sst-2-english||T5 | P66: =IF(COUNTIF($O$2:O66, O66)=1, 1, 0) -> 1 | Q66: =A66& "||" & X66 -> 64||C32 | R66: =IF(COUNTIF($Q$2:Q66, Q66)=1, 1, 0) -> 1 | S66: =A66& "||" & Y66 -> 64||M7 | T66: =IF(COUNTIF($S$2:S66, S66)=1, 1, 0) -> 1 | U66: =A66& "||" & Z66 -> 64||T5 | V66: =IF(COUNTIF($U$2:U66, U66)=1, 1, 0) -> 1 | W66: Adding Preloaded a pretrained sentiment model to avoid runtime downloads. | X66: C32 | Y66: =_xlfn.XLOOKUP(X66, codes!A:A, codes!F:F, "") -> M7 | Z66: =_xlfn.XLOOKUP(Y66, 'sub-themes'!A:A, 'sub-themes'!H:H, "") -> T5
A67: 65 | B67: 118 | C67: commit | D67: 6 | E67: 2 | F67: ['add'] | G67: ['spacy/da_core_news_sm', 'spacy/da_core_news_trf'] | H67: =SUBSTITUTE(SUBSTITUTE(SUBSTITUTE(SUBSTITUTE(G67,"[",""),"]",""),"'",""),", ","|") -> spacy/da_core_news_sm|spacy/da_core_news_trf | I67: =B67 & "||" & F67 & "||" & H67 -> 118||['add']||spacy/da_core_news_sm|spacy/da_core_news_trf | J67: =IF(COUNTIF($I$2:I67, I67)=1, 1, 0) -> 1 | K67: =I67 & "||" & X67 -> 118||['add']||spacy/da_core_news_sm|spacy/da_core_news_trf||C4 | L67: =IF(COUNTIF($K$2:K67, K67)=1, 1, 0) -> 1 | M67: =I67 & "||" & Y67 -> 118||['add']||spacy/da_core_news_sm|spacy/da_core_news_trf||M1 | N67: =IF(COUNTIF($M$2:M67, M67)=1, 1, 0) -> 1 | O67: =I67 & "||" & Z67 -> 118||['add']||spacy/da_core_news_sm|spacy/da_core_news_trf||T1 | P67: =IF(COUNTIF($O$2:O67, O67)=1, 1, 0) -> 1 | Q67: =A67& "||" & X67 -> 65||C4 | R67: =IF(COUNTIF($Q$2:Q67, Q67)=1, 1, 0) -> 1 | S67: =A67& "||" & Y67 -> 65||M1 | T67: =IF(COUNTIF($S$2:S67, S67)=1, 1, 0) -> 1 | U67: =A67& "||" & Z67 -> 65||T1 | V67: =IF(COUNTIF($U$2:U67, U67)=1, 1, 0) -> 1 | W67: Added spacy component for relations extractions using prompts | X67: C4 | Y67: =_xlfn.XLOOKUP(X67, codes!A:A, codes!F:F, "") -> M1 | Z67: =_xlfn.XLOOKUP(Y67, 'sub-themes'!A:A, 'sub-themes'!H:H, "") -> T1
A68: 66 | B68: 118 | C68: pull_request | D68: 6 | E68: 2 | F68: ['add'] | G68: ['spacy/da_core_news_sm', 'spacy/da_core_news_trf'] | H68: =SUBSTITUTE(SUBSTITUTE(SUBSTITUTE(SUBSTITUTE(G68,"[",""),"]",""),"'",""),", ","|") -> spacy/da_core_news_sm|spacy/da_core_news_trf | I68: =B68 & "||" & F68 & "||" & H68 -> 118||['add']||spacy/da_core_news_sm|spacy/da_core_news_trf | J68: =IF(COUNTIF($I$2:I68, I68)=1, 1, 0) -> 0 | K68: =I68 & "||" & X68 -> 118||['add']||spacy/da_core_news_sm|spacy/da_core_news_trf||C4 | L68: =IF(COUNTIF($K$2:K68, K68)=1, 1, 0) -> 0 | M68: =I68 & "||" & Y68 -> 118||['add']||spacy/da_core_news_sm|spacy/da_core_news_trf||M1 | N68: =IF(COUNTIF($M$2:M68, M68)=1, 1, 0) -> 0 | O68: =I68 & "||" & Z68 -> 118||['add']||spacy/da_core_news_sm|spacy/da_core_news_trf||T1 | P68: =IF(COUNTIF($O$2:O68, O68)=1, 1, 0) -> 0 | Q68: =A68& "||" & X68 -> 66||C4 | R68: =IF(COUNTIF($Q$2:Q68, Q68)=1, 1, 0) -> 1 | S68: =A68& "||" & Y68 -> 66||M1 | T68: =IF(COUNTIF($S$2:S68, S68)=1, 1, 0) -> 1 | U68: =A68& "||" & Z68 -> 66||T1 | V68: =IF(COUNTIF($U$2:U68, U68)=1, 1, 0) -> 1 | W68: Added spacy component for relations extractions using prompts | X68: C4 | Y68: =_xlfn.XLOOKUP(X68, codes!A:A, codes!F:F, "") -> M1 | Z68: =_xlfn.XLOOKUP(Y68, 'sub-themes'!A:A, 'sub-themes'!H:H, "") -> T1
A69: 67 | B69: 119 | C69: release_note | D69: 10 | E69: 2 | F69: ['add'] | G69: ['stabilityai/stable-diffusion-2-1', 'stabilityai/stable-diffusion-2-1-base'] | H69: =SUBSTITUTE(SUBSTITUTE(SUBSTITUTE(SUBSTITUTE(G69,"[",""),"]",""),"'",""),", ","|") -> stabilityai/stable-diffusion-2-1|stabilityai/stable-diffusion-2-1-base | I69: =B69 & "||" & F69 & "||" & H69 -> 119||['add']||stabilityai/stable-diffusion-2-1|stabilityai/stable-diffusion-2-1-base | J69: =IF(COUNTIF($I$2:I69, I69)=1, 1, 0) -> 1 | K69: =I69 & "||" & X69 -> 119||['add']||stabilityai/stable-diffusion-2-1|stabilityai/stable-diffusion-2-1-base||C31 | L69: =IF(COUNTIF($K$2:K69, K69)=1, 1, 0) -> 1 | M69: =I69 & "||" & Y69 -> 119||['add']||stabilityai/stable-diffusion-2-1|stabilityai/stable-diffusion-2-1-base||M4 | N69: =IF(COUNTIF($M$2:M69, M69)=1, 1, 0) -> 1 | O69: =I69 & "||" & Z69 -> 119||['add']||stabilityai/stable-diffusion-2-1|stabilityai/stable-diffusion-2-1-base||T1 | P69: =IF(COUNTIF($O$2:O69, O69)=1, 1, 0) -> 1 | Q69: =A69& "||" & X69 -> 67||C31 | R69: =IF(COUNTIF($Q$2:Q69, Q69)=1, 1, 0) -> 1 | S69: =A69& "||" & Y69 -> 67||M4 | T69: =IF(COUNTIF($S$2:S69, S69)=1, 1, 0) -> 1 | U69: =A69& "||" & Z69 -> 67||T1 | V69: =IF(COUNTIF($U$2:U69, U69)=1, 1, 0) -> 1 | W69: Added Stable Diffusion 2.1 for computer vision functionality (text-to-image inference) | X69: C31 | Y69: =_xlfn.XLOOKUP(X69, codes!A:A, codes!F:F, "") -> M4 | Z69: =_xlfn.XLOOKUP(Y69, 'sub-themes'!A:A, 'sub-themes'!H:H, "") -> T1
A70: 68 | B70: 122 | C70: release_note | D70: 9 | E70: 2 | F70: ['add'] | G70: ['stanfordnlp/stanza-en', 'stanfordnlp/stanza-de'] | H70: =SUBSTITUTE(SUBSTITUTE(SUBSTITUTE(SUBSTITUTE(G70,"[",""),"]",""),"'",""),", ","|") -> stanfordnlp/stanza-en|stanfordnlp/stanza-de | I70: =B70 & "||" & F70 & "||" & H70 -> 122||['add']||stanfordnlp/stanza-en|stanfordnlp/stanza-de | J70: =IF(COUNTIF($I$2:I70, I70)=1, 1, 0) -> 1 | K70: =I70 & "||" & X70 -> 122||['add']||stanfordnlp/stanza-en|stanfordnlp/stanza-de||C33 | L70: =IF(COUNTIF($K$2:K70, K70)=1, 1, 0) -> 1 | M70: =I70 & "||" & Y70 -> 122||['add']||stanfordnlp/stanza-en|stanfordnlp/stanza-de||M1 | N70: =IF(COUNTIF($M$2:M70, M70)=1, 1, 0) -> 1 | O70: =I70 & "||" & Z70 -> 122||['add']||stanfordnlp/stanza-en|stanfordnlp/stanza-de||T1 | P70: =IF(COUNTIF($O$2:O70, O70)=1, 1, 0) -> 1 | Q70: =A70& "||" & X70 -> 68||C33 | R70: =IF(COUNTIF($Q$2:Q70, Q70)=1, 1, 0) -> 1 | S70: =A70& "||" & Y70 -> 68||M1 | T70: =IF(COUNTIF($S$2:S70, S70)=1, 1, 0) -> 1 | U70: =A70& "||" & Z70 -> 68||T1 | V70: =IF(COUNTIF($U$2:U70, U70)=1, 1, 0) -> 1 | W70: Introduce stanza model for sentiment analysis for English | X70: C33 | Y70: =_xlfn.XLOOKUP(X70, codes!A:A, codes!F:F, "") -> M1 | Z70: =_xlfn.XLOOKUP(Y70, 'sub-themes'!A:A, 'sub-themes'!H:H, "") -> T1
A71: 69 | B71: 123 | C71: commit | D71: 2 | E71: 1 | F71: ['add'] | G71: ['stanfordnlp/stanza-th'] | H71: =SUBSTITUTE(SUBSTITUTE(SUBSTITUTE(SUBSTITUTE(G71,"[",""),"]",""),"'",""),", ","|") -> stanfordnlp/stanza-th | I71: =B71 & "||" & F71 & "||" & H71 -> 123||['add']||stanfordnlp/stanza-th | J71: =IF(COUNTIF($I$2:I71, I71)=1, 1, 0) -> 1 | K71: =I71 & "||" & X71 -> 123||['add']||stanfordnlp/stanza-th||C21 | L71: =IF(COUNTIF($K$2:K71, K71)=1, 1, 0) -> 1 | M71: =I71 & "||" & Y71 -> 123||['add']||stanfordnlp/stanza-th||M2 | N71: =IF(COUNTIF($M$2:M71, M71)=1, 1, 0) -> 1 | O71: =I71 & "||" & Z71 -> 123||['add']||stanfordnlp/stanza-th||T2 | P71: =IF(COUNTIF($O$2:O71, O71)=1, 1, 0) -> 1 | Q71: =A71& "||" & X71 -> 69||C21 | R71: =IF(COUNTIF($Q$2:Q71, Q71)=1, 1, 0) -> 1 | S71: =A71& "||" & Y71 -> 69||M2 | T71: =IF(COUNTIF($S$2:S71, S71)=1, 1, 0) -> 1 | U71: =A71& "||" & Z71 -> 69||T2 | V71: =IF(COUNTIF($U$2:U71, U71)=1, 1, 0) -> 1 | W71: Integrate stanza model with PyThaiNLP as an external Thai tokenizer | X71: C21 | Y71: =_xlfn.XLOOKUP(X71, codes!A:A, codes!F:F, "") -> M2 | Z71: =_xlfn.XLOOKUP(Y71, 'sub-themes'!A:A, 'sub-themes'!H:H, "") -> T2
A72: 70 | B72: 124 | C72: commit | D72: 1 | E72: 1 | F72: ['add'] | G72: ['facebook/bart-large-mnli'] | H72: =SUBSTITUTE(SUBSTITUTE(SUBSTITUTE(SUBSTITUTE(G72,"[",""),"]",""),"'",""),", ","|") -> facebook/bart-large-mnli | I72: =B72 & "||" & F72 & "||" & H72 -> 124||['add']||facebook/bart-large-mnli | J72: =IF(COUNTIF($I$2:I72, I72)=1, 1, 0) -> 1 | K72: =I72 & "||" & X72 -> 124||['add']||facebook/bart-large-mnli||C34 | L72: =IF(COUNTIF($K$2:K72, K72)=1, 1, 0) -> 1 | M72: =I72 & "||" & Y72 -> 124||['add']||facebook/bart-large-mnli||M1 | N72: =IF(COUNTIF($M$2:M72, M72)=1, 1, 0) -> 1 | O72: =I72 & "||" & Z72 -> 124||['add']||facebook/bart-large-mnli||T1 | P72: =IF(COUNTIF($O$2:O72, O72)=1, 1, 0) -> 1 | Q72: =A72& "||" & X72 -> 70||C34 | R72: =IF(COUNTIF($Q$2:Q72, Q72)=1, 1, 0) -> 1 | S72: =A72& "||" & Y72 -> 70||M1 | T72: =IF(COUNTIF($S$2:S72, S72)=1, 1, 0) -> 1 | U72: =A72& "||" & Z72 -> 70||T1 | V72: =IF(COUNTIF($U$2:U72, U72)=1, 1, 0) -> 1 | W72: Added a pretrained model for text classification tasks. | X72: C34 | Y72: =_xlfn.XLOOKUP(X72, codes!A:A, codes!F:F, "") -> M1 | Z72: =_xlfn.XLOOKUP(Y72, 'sub-themes'!A:A, 'sub-themes'!H:H, "") -> T1
A73: 71 | B73: 128 | C73: commit | D73: 2 | E73: 1 | F73: ['migrate'] | G73: ['prajjwal1/bert-tiny'] | H73: =SUBSTITUTE(SUBSTITUTE(SUBSTITUTE(SUBSTITUTE(G73,"[",""),"]",""),"'",""),", ","|") -> prajjwal1/bert-tiny | I73: =B73 & "||" & F73 & "||" & H73 -> 128||['migrate']||prajjwal1/bert-tiny | J73: =IF(COUNTIF($I$2:I73, I73)=1, 1, 0) -> 1 | K73: =I73 & "||" & X73 -> 128||['migrate']||prajjwal1/bert-tiny||C22 | L73: =IF(COUNTIF($K$2:K73, K73)=1, 1, 0) -> 1 | M73: =I73 & "||" & Y73 -> 128||['migrate']||prajjwal1/bert-tiny||M22 | N73: =IF(COUNTIF($M$2:M73, M73)=1, 1, 0) -> 1 | O73: =I73 & "||" & Z73 -> 128||['migrate']||prajjwal1/bert-tiny||T5 | P73: =IF(COUNTIF($O$2:O73, O73)=1, 1, 0) -> 1 | Q73: =A73& "||" & X73 -> 71||C22 | R73: =IF(COUNTIF($Q$2:Q73, Q73)=1, 1, 0) -> 1 | S73: =A73& "||" & Y73 -> 71||M22 | T73: =IF(COUNTIF($S$2:S73, S73)=1, 1, 0) -> 1 | U73: =A73& "||" & Z73 -> 71||T5 | V73: =IF(COUNTIF($U$2:U73, U73)=1, 1, 0) -> 1 | W73: Migrated to a smaller BERT model to reduce memory usage in tests. | X73: C22 | Y73: =_xlfn.XLOOKUP(X73, codes!A:A, codes!F:F, "") -> M22 | Z73: =_xlfn.XLOOKUP(Y73, 'sub-themes'!A:A, 'sub-themes'!H:H, "") -> T5
A74: 72 | B74: 129 | C74: release_note | D74: 4 | E74: 1 | F74: ['add'] | G74: ['sentence-transformers/all-minilm-l6-v2'] | H74: =SUBSTITUTE(SUBSTITUTE(SUBSTITUTE(SUBSTITUTE(G74,"[",""),"]",""),"'",""),", ","|") -> sentence-transformers/all-minilm-l6-v2 | I74: =B74 & "||" & F74 & "||" & H74 -> 129||['add']||sentence-transformers/all-minilm-l6-v2 | J74: =IF(COUNTIF($I$2:I74, I74)=1, 1, 0) -> 1 | K74: =I74 & "||" & X74 -> 129||['add']||sentence-transformers/all-minilm-l6-v2||C56 | L74: =IF(COUNTIF($K$2:K74, K74)=1, 1, 0) -> 1 | M74: =I74 & "||" & Y74 -> 129||['add']||sentence-transformers/all-minilm-l6-v2||M21 | N74: =IF(COUNTIF($M$2:M74, M74)=1, 1, 0) -> 1 | O74: =I74 & "||" & Z74 -> 129||['add']||sentence-transformers/all-minilm-l6-v2||T2 | P74: =IF(COUNTIF($O$2:O74, O74)=1, 1, 0) -> 1 | Q74: =A74& "||" & X74 -> 72||C56 | R74: =IF(COUNTIF($Q$2:Q74, Q74)=1, 1, 0) -> 1 | S74: =A74& "||" & Y74 -> 72||M21 | T74: =IF(COUNTIF($S$2:S74, S74)=1, 1, 0) -> 1 | U74: =A74& "||" & Z74 -> 72||T2 | V74: =IF(COUNTIF($U$2:U74, U74)=1, 1, 0) -> 1 | W74: Added sentence-transformers model support to enable feature extraction pipelines. | X74: C56 | Y74: =_xlfn.XLOOKUP(X74, codes!A:A, codes!F:F, "") -> M21 | Z74: =_xlfn.XLOOKUP(Y74, 'sub-themes'!A:A, 'sub-themes'!H:H, "") -> T2
A75: 73 | B75: 129 | C75: commit | D75: 4 | E75: 1 | F75: ['add'] | G75: ['sentence-transformers/all-minilm-l6-v2'] | H75: =SUBSTITUTE(SUBSTITUTE(SUBSTITUTE(SUBSTITUTE(G75,"[",""),"]",""),"'",""),", ","|") -> sentence-transformers/all-minilm-l6-v2 | I75: =B75 & "||" & F75 & "||" & H75 -> 129||['add']||sentence-transformers/all-minilm-l6-v2 | J75: =IF(COUNTIF($I$2:I75, I75)=1, 1, 0) -> 0 | K75: =I75 & "||" & X75 -> 129||['add']||sentence-transformers/all-minilm-l6-v2||C56 | L75: =IF(COUNTIF($K$2:K75, K75)=1, 1, 0) -> 0 | M75: =I75 & "||" & Y75 -> 129||['add']||sentence-transformers/all-minilm-l6-v2||M21 | N75: =IF(COUNTIF($M$2:M75, M75)=1, 1, 0) -> 0 | O75: =I75 & "||" & Z75 -> 129||['add']||sentence-transformers/all-minilm-l6-v2||T2 | P75: =IF(COUNTIF($O$2:O75, O75)=1, 1, 0) -> 0 | Q75: =A75& "||" & X75 -> 73||C56 | R75: =IF(COUNTIF($Q$2:Q75, Q75)=1, 1, 0) -> 1 | S75: =A75& "||" & Y75 -> 73||M21 | T75: =IF(COUNTIF($S$2:S75, S75)=1, 1, 0) -> 1 | U75: =A75& "||" & Z75 -> 73||T2 | V75: =IF(COUNTIF($U$2:U75, U75)=1, 1, 0) -> 1 | W75: Add support for feature extraction pipelines to transformers | X75: C56 | Y75: =_xlfn.XLOOKUP(X75, codes!A:A, codes!F:F, "") -> M21 | Z75: =_xlfn.XLOOKUP(Y75, 'sub-themes'!A:A, 'sub-themes'!H:H, "") -> T2
A76: 74 | B76: 129 | C76: pull_request | D76: 4 | E76: 1 | F76: ['add'] | G76: ['sentence-transformers/all-minilm-l6-v2'] | H76: =SUBSTITUTE(SUBSTITUTE(SUBSTITUTE(SUBSTITUTE(G76,"[",""),"]",""),"'",""),", ","|") -> sentence-transformers/all-minilm-l6-v2 | I76: =B76 & "||" & F76 & "||" & H76 -> 129||['add']||sentence-transformers/all-minilm-l6-v2 | J76: =IF(COUNTIF($I$2:I76, I76)=1, 1, 0) -> 0 | K76: =I76 & "||" & X76 -> 129||['add']||sentence-transformers/all-minilm-l6-v2||C56 | L76: =IF(COUNTIF($K$2:K76, K76)=1, 1, 0) -> 0 | M76: =I76 & "||" & Y76 -> 129||['add']||sentence-transformers/all-minilm-l6-v2||M21 | N76: =IF(COUNTIF($M$2:M76, M76)=1, 1, 0) -> 0 | O76: =I76 & "||" & Z76 -> 129||['add']||sentence-transformers/all-minilm-l6-v2||T2 | P76: =IF(COUNTIF($O$2:O76, O76)=1, 1, 0) -> 0 | Q76: =A76& "||" & X76 -> 74||C56 | R76: =IF(COUNTIF($Q$2:Q76, Q76)=1, 1, 0) -> 1 | S76: =A76& "||" & Y76 -> 74||M21 | T76: =IF(COUNTIF($S$2:S76, S76)=1, 1, 0) -> 1 | U76: =A76& "||" & Z76 -> 74||T2 | V76: =IF(COUNTIF($U$2:U76, U76)=1, 1, 0) -> 1 | W76: Adds support for FeatureExtractionPipelines (sentence-transformers, per popular request) to the transformers flavor. | X76: C56 | Y76: =_xlfn.XLOOKUP(X76, codes!A:A, codes!F:F, "") -> M21 | Z76: =_xlfn.XLOOKUP(Y76, 'sub-themes'!A:A, 'sub-themes'!H:H, "") -> T2
... A119: 112 | B119: 176 | C119: commit | D119: 7 | E119: 6 | F119: ['remove'] | G119: ['thudm/chatglm3-6b', 'thudm/glm-4-9b-chat', 'deepseek-ai/deepseek-v2-lite', 'deepseek-ai/deepseek-coder-1.3b-instruct', 'thudm/codegeex4-all-9b', 'opengvlab/mini-internvl-chat-4b-v1-5'] | H119: =SUBSTITUTE(SUBSTITUTE(SUBSTITUTE(SUBSTITUTE(G119,"[",""),"]",""),"'",""),", ","|") -> thudm/chatglm3-6b|thudm/glm-4-9b-chat|deepseek-ai/deepseek-v2-lite|deepseek-ai/deepseek-coder-1.3b-instruct|thudm/codegeex4-all-9b|opengvlab/mini-internvl-chat-4b-v1-5 | I119: =B119 & "||" & F119 & "||" & H119 -> 176||['remove']||thudm/chatglm3-6b|thudm/glm-4-9b-chat|deepseek-ai/deepseek-v2-lite|deepseek-ai/deepseek-coder-1.3b-instruct|thudm/codegeex4-all-9b|opengvlab/mini-internvl-chat-4b-v1-5 | J119: =IF(COUNTIF($I$2:I119, I119)=1, 1, 0) -> 1 | K119: =I119 & "||" & X119 -> 176||['remove']||thudm/chatglm3-6b|thudm/glm-4-9b-chat|deepseek-ai/deepseek-v2-lite|deepseek-ai/deepseek-coder-1.3b-instruct|thudm/codegeex4-all-9b|opengvlab/mini-internvl-chat-4b-v1-5||C37 | L119: =IF(COUNTIF($K$2:K119, K119)=1, 1, 0) -> 1 | M119: =I119 & "||" & Y119 -> 176||['remove']||thudm/chatglm3-6b|thudm/glm-4-9b-chat|deepseek-ai/deepseek-v2-lite|deepseek-ai/deepseek-coder-1.3b-instruct|thudm/codegeex4-all-9b|opengvlab/mini-internvl-chat-4b-v1-5||M37 | N119: =IF(COUNTIF($M$2:M119, M119)=1, 1, 0) -> 1 | O119: =I119 & "||" & Z119 -> 176||['remove']||thudm/chatglm3-6b|thudm/glm-4-9b-chat|deepseek-ai/deepseek-v2-lite|deepseek-ai/deepseek-coder-1.3b-instruct|thudm/codegeex4-all-9b|opengvlab/mini-internvl-chat-4b-v1-5||T4 | P119: =IF(COUNTIF($O$2:O119, O119)=1, 1, 0) -> 1 | Q119: =A119& "||" & X119 -> 112||C37 | R119: =IF(COUNTIF($Q$2:Q119, Q119)=1, 1, 0) -> 1 | S119: =A119& "||" & Y119 -> 112||M37 | T119: =IF(COUNTIF($S$2:S119, S119)=1, 1, 0) -> 1 | U119: =A119& "||" & Z119 -> 112||T4 | V119: =IF(COUNTIF($U$2:U119, U119)=1, 1, 0) -> 1 | W119: Remove the models because the current version of the software project no longer supports them (deprecated). | X119: C37 | Y119: =_xlfn.XLOOKUP(X119, codes!A:A, codes!F:F, "") -> M37 | Z119: =_xlfn.XLOOKUP(Y119, 'sub-themes'!A:A, 'sub-themes'!H:H, "") -> T4
A120: 113 | B120: 179 | C120: commit | D120: 28 | E120: 5 | F120: ['add'] | G120: ['trl-internal-testing/tiny-qwen2forcausallm-2.5', 'trl-internal-testing/tiny-t5forconditionalgeneration', 'trl-internal-testing/tiny-bartmodel', 'trl-internal-testing/tiny-mistralforcausallm-0.1', 'trl-internal-testing/tiny-llavaforconditionalgeneration'] | H120: =SUBSTITUTE(SUBSTITUTE(SUBSTITUTE(SUBSTITUTE(G120,"[",""),"]",""),"'",""),", ","|") -> trl-internal-testing/tiny-qwen2forcausallm-2.5|trl-internal-testing/tiny-t5forconditionalgeneration|trl-internal-testing/tiny-bartmodel|trl-internal-testing/tiny-mistralforcausallm-0.1|trl-internal-testing/tiny-llavaforconditionalgeneration | I120: =B120 & "||" & F120 -> 179||['add'] | J120: =IF(COUNTIF($I$2:I120, I120)=1, 1, 0) -> 1 | K120: =I120 & "||" & X120 -> 179||['add']||C62 | L120: =IF(COUNTIF($K$2:K120, K120)=1, 1, 0) -> 1 | M120: =I120 & "||" & Y120 -> 179||['add']||M11 | N120: =IF(COUNTIF($M$2:M120, M120)=1, 1, 0) -> 1 | O120: =I120 & "||" & Z120 -> 179||['add']||T3 | P120: =IF(COUNTIF($O$2:O120, O120)=1, 1, 0) -> 1 | Q120: =A120& "||" & X120 -> 113||C62 | R120: =IF(COUNTIF($Q$2:Q120, Q120)=1, 1, 0) -> 1 | S120: =A120& "||" & Y120 -> 113||M11 | T120: =IF(COUNTIF($S$2:S120, S120)=1, 1, 0) -> 1 | U120: =A120& "||" & Z120 -> 113||T3 | V120: =IF(COUNTIF($U$2:U120, U120)=1, 1, 0) -> 1 | W120: Add new models for testing their trainer functionalities | X120: C62 | Y120: =_xlfn.XLOOKUP(X120, codes!A:A, codes!F:F, "") -> M11 | Z120: =_xlfn.XLOOKUP(Y120, 'sub-themes'!A:A, 'sub-themes'!H:H, "") -> T3
A121: 114 | B121: 179 | C121: pull_request | D121: 8 | E121: 1 | F121: ['migrate'] | G121: ['trl-internal-testing/tiny-qwen2forcausallm-2.5'] | H121: =SUBSTITUTE(SUBSTITUTE(SUBSTITUTE(SUBSTITUTE(G121,"[",""),"]",""),"'",""),", ","|") -> trl-internal-testing/tiny-qwen2forcausallm-2.5 | I121: =B121 & "||" & F121 & "||" & H121 -> 179||['migrate']||trl-internal-testing/tiny-qwen2forcausallm-2.5 | J121: =IF(COUNTIF($I$2:I121, I121)=1, 1, 0) -> 1 | K121: =I121 & "||" & X121 -> 179||['migrate']||trl-internal-testing/tiny-qwen2forcausallm-2.5||C6 | L121: =IF(COUNTIF($K$2:K121, K121)=1, 1, 0) -> 1 | M121: =I121 & "||" & Y121 -> 179||['migrate']||trl-internal-testing/tiny-qwen2forcausallm-2.5||M6 | N121: =IF(COUNTIF($M$2:M121, M121)=1, 1, 0) -> 1 | O121: =I121 & "||" & Z121 -> 179||['migrate']||trl-internal-testing/tiny-qwen2forcausallm-2.5||T4 | P121: =IF(COUNTIF($O$2:O121, O121)=1, 1, 0) -> 1 | Q121: =A121& "||" & X121 -> 114||C6 | R121: =IF(COUNTIF($Q$2:Q121, Q121)=1, 1, 0) -> 1 | S121: =A121& "||" & Y121 -> 114||M6 | T121: =IF(COUNTIF($S$2:S121, S121)=1, 1, 0) -> 1 | U121: =A121& "||" & Z121 -> 114||T4 | V121: =IF(COUNTIF($U$2:U121, U121)=1, 1, 0) -> 1 | W121: Migrate to new models for testing that have the same/consistent namespaces because the original models lack uniformity | X121: C6 | Y121: =_xlfn.XLOOKUP(X121, codes!A:A, codes!F:F, "") -> M6 | Z121: =_xlfn.XLOOKUP(Y121, 'sub-themes'!A:A, 'sub-themes'!H:H, "") -> T4
A122: 114 | B122: 179 | C122: pull_request | D122: 8 | E122: 1 | F122: ['migrate'] | G122: ['trl-internal-testing/tiny-qwen2forcausallm-2.5'] | H122: =SUBSTITUTE(SUBSTITUTE(SUBSTITUTE(SUBSTITUTE(G122,"[",""),"]",""),"'",""),", ","|") -> trl-internal-testing/tiny-qwen2forcausallm-2.5 | I122: =B122 & "||" & F122 & "||" & H122 -> 179||['migrate']||trl-internal-testing/tiny-qwen2forcausallm-2.5 | J122: =IF(COUNTIF($I$2:I122, I122)=1, 1, 0) -> 0 | K122: =I122 & "||" & X122 -> 179||['migrate']||trl-internal-testing/tiny-qwen2forcausallm-2.5||C59 | L122: =IF(COUNTIF($K$2:K122, K122)=1, 1, 0) -> 1 | M122: =I122 & "||" & Y122 -> 179||['migrate']||trl-internal-testing/tiny-qwen2forcausallm-2.5||M22 | N122: =IF(COUNTIF($M$2:M122, M122)=1, 1, 0) -> 1 | O122: =I122 & "||" & Z122 -> 179||['migrate']||trl-internal-testing/tiny-qwen2forcausallm-2.5||T5 | P122: =IF(COUNTIF($O$2:O122, O122)=1, 1, 0) -> 1 | Q122: =A122& "||" & X122 -> 114||C59 | R122: =IF(COUNTIF($Q$2:Q122, Q122)=1, 1, 0) -> 1 | S122: =A122& "||" & Y122 -> 114||M22 | T122: =IF(COUNTIF($S$2:S122, S122)=1, 1, 0) -> 1 | U122: =A122& "||" & Z122 -> 114||T5 | V122: =IF(COUNTIF($U$2:U122, U122)=1, 1, 0) -> 1 | W122: Migrate to smaller model to speed up testing | X122: C59 | Y122: =_xlfn.XLOOKUP(X122, codes!A:A, codes!F:F, "") -> M22 | Z122: =_xlfn.XLOOKUP(Y122, 'sub-themes'!A:A, 'sub-themes'!H:H, "") -> T5
A123: 115 | B123: 180 | C123: code_comment | D123: 1 | E123: 1 | F123: ['add'] | G123: ['qwen/qwen2.5-32b-instruct'] | H123: =SUBSTITUTE(SUBSTITUTE(SUBSTITUTE(SUBSTITUTE(G123,"[",""),"]",""),"'",""),", ","|") -> qwen/qwen2.5-32b-instruct | I123: =B123 & "||" & F123 & "||" & H123 -> 180||['add']||qwen/qwen2.5-32b-instruct | J123: =IF(COUNTIF($I$2:I123, I123)=1, 1, 0) -> 1 | K123: =I123 & "||" & X123 -> 180||['add']||qwen/qwen2.5-32b-instruct||C38 | L123: =IF(COUNTIF($K$2:K123, K123)=1, 1, 0) -> 1 | M123: =I123 & "||" & Y123 -> 180||['add']||qwen/qwen2.5-32b-instruct||M6 | N123: =IF(COUNTIF($M$2:M123, M123)=1, 1, 0) -> 1 | O123: =I123 & "||" & Z123 -> 180||['add']||qwen/qwen2.5-32b-instruct||T4 | P123: =IF(COUNTIF($O$2:O123, O123)=1, 1, 0) -> 1 | Q123: =A123& "||" & X123 -> 115||C38 | R123: =IF(COUNTIF($Q$2:Q123, Q123)=1, 1, 0) -> 1 | S123: =A123& "||" & Y123 -> 115||M6 | T123: =IF(COUNTIF($S$2:S123, S123)=1, 1, 0) -> 1 | U123: =A123& "||" & Z123 -> 115||T4 | V123: =IF(COUNTIF($U$2:U123, U123)=1, 1, 0) -> 1 | W123: Add a slightly larger Qwen2.5 model because vLLM testing requires compatible hidden-size/head dimensions (meeting architectural constraints imposed by vLLM integration). | X123: C38 | Y123: =_xlfn.XLOOKUP(X123, codes!A:A, codes!F:F, "") -> M6 | Z123: =_xlfn.XLOOKUP(Y123, 'sub-themes'!A:A, 'sub-themes'!H:H, "") -> T4
A124: 116 | B124: 182 | C124: release_note | D124: 2 | E124: 1 | F124: ['remove'] | G124: ['trl-internal-testing/tiny-qwen2forcausallm-2.5'] | H124: =SUBSTITUTE(SUBSTITUTE(SUBSTITUTE(SUBSTITUTE(G124,"[",""),"]",""),"'",""),", ","|") -> trl-internal-testing/tiny-qwen2forcausallm-2.5 | I124: =B124 & "||" & F124 & "||" & H124 -> 182||['remove']||trl-internal-testing/tiny-qwen2forcausallm-2.5 | J124: =IF(COUNTIF($I$2:I124, I124)=1, 1, 0) -> 1 | K124: =I124 & "||" & X124 -> 182||['remove']||trl-internal-testing/tiny-qwen2forcausallm-2.5||C37 | L124: =IF(COUNTIF($K$2:K124, K124)=1, 1, 0) -> 1 | M124: =I124 & "||" & Y124 -> 182||['remove']||trl-internal-testing/tiny-qwen2forcausallm-2.5||M37 | N124: =IF(COUNTIF($M$2:M124, M124)=1, 1, 0) -> 1 | O124: =I124 & "||" & Z124 -> 182||['remove']||trl-internal-testing/tiny-qwen2forcausallm-2.5||T4 | P124: =IF(COUNTIF($O$2:O124, O124)=1, 1, 0) -> 1 | Q124: =A124& "||" & X124 -> 116||C37 | R124: =IF(COUNTIF($Q$2:Q124, Q124)=1, 1, 0) -> 1 | S124: =A124& "||" & Y124 -> 116||M37 | T124: =IF(COUNTIF($S$2:S124, S124)=1, 1, 0) -> 1 | U124: =A124& "||" & Z124 -> 116||T4 | V124: =IF(COUNTIF($U$2:U124, U124)=1, 1, 0) -> 1 | W124: Remove the testing models because the current version of the software project no longer supports them (deprecated). | X124: C37 | Y124: =_xlfn.XLOOKUP(X124, codes!A:A, codes!F:F, "") -> M37 | Z124: =_xlfn.XLOOKUP(Y124, 'sub-themes'!A:A, 'sub-themes'!H:H, "") -> T4
A125: 117 | B125: 182 | C125: commit | D125: 2 | E125: 1 | F125: ['remove'] | G125: ['trl-internal-testing/tiny-qwen2forcausallm-2.5'] | H125: =SUBSTITUTE(SUBSTITUTE(SUBSTITUTE(SUBSTITUTE(G125,"[",""),"]",""),"'",""),", ","|") -> trl-internal-testing/tiny-qwen2forcausallm-2.5 | I125: =B125 & "||" & F125 & "||" & H125 -> 182||['remove']||trl-internal-testing/tiny-qwen2forcausallm-2.5 | J125: =IF(COUNTIF($I$2:I125, I125)=1, 1, 0) -> 0 | K125: =I125 & "||" & X125 -> 182||['remove']||trl-internal-testing/tiny-qwen2forcausallm-2.5||C37 | L125: =IF(COUNTIF($K$2:K125, K125)=1, 1, 0) -> 0 | M125: =I125 & "||" & Y125 -> 182||['remove']||trl-internal-testing/tiny-qwen2forcausallm-2.5||M37 | N125: =IF(COUNTIF($M$2:M125, M125)=1, 1, 0) -> 0 | O125: =I125 & "||" & Z125 -> 182||['remove']||trl-internal-testing/tiny-qwen2forcausallm-2.5||T4 | P125: =IF(COUNTIF($O$2:O125, O125)=1, 1, 0) -> 0 | Q125: =A125& "||" & X125 -> 117||C37 | R125: =IF(COUNTIF($Q$2:Q125, Q125)=1, 1, 0) -> 1 | S125: =A125& "||" & Y125 -> 117||M37 | T125: =IF(COUNTIF($S$2:S125, S125)=1, 1, 0) -> 1 | U125: =A125& "||" & Z125 -> 117||T4 | V125: =IF(COUNTIF($U$2:U125, U125)=1, 1, 0) -> 1 | W125: Remove the testing models because the current version of the software project no longer supports them (deprecated). | X125: C37 | Y125: =_xlfn.XLOOKUP(X125, codes!A:A, codes!F:F, "") -> M37 | Z125: =_xlfn.XLOOKUP(Y125, 'sub-themes'!A:A, 'sub-themes'!H:H, "") -> T4
A126: 118 | B126: 182 | C126: pull_request | D126: 2 | E126: 1 | F126: ['remove'] | G126: ['trl-internal-testing/tiny-qwen2forcausallm-2.5'] | H126: =SUBSTITUTE(SUBSTITUTE(SUBSTITUTE(SUBSTITUTE(G126,"[",""),"]",""),"'",""),", ","|") -> trl-internal-testing/tiny-qwen2forcausallm-2.5 | I126: =B126 & "||" & F126 & "||" & H126 -> 182||['remove']||trl-internal-testing/tiny-qwen2forcausallm-2.5 | J126: =IF(COUNTIF($I$2:I126, I126)=1, 1, 0) -> 0 | K126: =I126 & "||" & X126 -> 182||['remove']||trl-internal-testing/tiny-qwen2forcausallm-2.5||C37 | L126: =IF(COUNTIF($K$2:K126, K126)=1, 1, 0) -> 0 | M126: =I126 & "||" & Y126 -> 182||['remove']||trl-internal-testing/tiny-qwen2forcausallm-2.5||M37 | N126: =IF(COUNTIF($M$2:M126, M126)=1, 1, 0) -> 0 | O126: =I126 & "||" & Z126 -> 182||['remove']||trl-internal-testing/tiny-qwen2forcausallm-2.5||T4 | P126: =IF(COUNTIF($O$2:O126, O126)=1, 1, 0) -> 0 | Q126: =A126& "||" & X126 -> 118||C37 | R126: =IF(COUNTIF($Q$2:Q126, Q126)=1, 1, 0) -> 1 | S126: =A126& "||" & Y126 -> 118||M37 | T126: =IF(COUNTIF($S$2:S126, S126)=1, 1, 0) -> 1 | U126: =A126& "||" & Z126 -> 118||T4 | V126: =IF(COUNTIF($U$2:U126, U126)=1, 1, 0) -> 1 | W126: Remove the testing models because the current version of the software project no longer supports them (deprecated). | X126: C37 | Y126: =_xlfn.XLOOKUP(X126, codes!A:A, codes!F:F, "") -> M37 | Z126: =_xlfn.XLOOKUP(Y126, 'sub-themes'!A:A, 'sub-themes'!H:H, "") -> T4
A127: 119 | B127: 183 | C127: commit | D127: 2 | E127: 1 | F127: ['add'] | G127: ['sentence-transformers/multi-qa-mpnet-base-cos-v1'] | H127: =SUBSTITUTE(SUBSTITUTE(SUBSTITUTE(SUBSTITUTE(G127,"[",""),"]",""),"'",""),", ","|") -> sentence-transformers/multi-qa-mpnet-base-cos-v1 | I127: =B127 & "||" & F127 & "||" & H127 -> 183||['add']||sentence-transformers/multi-qa-mpnet-base-cos-v1 | J127: =IF(COUNTIF($I$2:I127, I127)=1, 1, 0) -> 1 | K127: =I127 & "||" & X127 -> 183||['add']||sentence-transformers/multi-qa-mpnet-base-cos-v1||C56 | L127: =IF(COUNTIF($K$2:K127, K127)=1, 1, 0) -> 1 | M127: =I127 & "||" & Y127 -> 183||['add']||sentence-transformers/multi-qa-mpnet-base-cos-v1||M21 | N127: =IF(COUNTIF($M$2:M127, M127)=1, 1, 0) -> 1 | O127: =I127 & "||" & Z127 -> 183||['add']||sentence-transformers/multi-qa-mpnet-base-cos-v1||T2 | P127: =IF(COUNTIF($O$2:O127, O127)=1, 1, 0) -> 1 | Q127: =A127& "||" & X127 -> 119||C56 | R127: =IF(COUNTIF($Q$2:Q127, Q127)=1, 1, 0) -> 1 | S127: =A127& "||" & Y127 -> 119||M21 | T127: =IF(COUNTIF($S$2:S127, S127)=1, 1, 0) -> 1 | U127: =A127& "||" & Z127 -> 119||T2 | V127: =IF(COUNTIF($U$2:U127, U127)=1, 1, 0) -> 1 | W127: Add the embedding model for chatbot | X127: C56 | Y127: =_xlfn.XLOOKUP(X127, codes!A:A, codes!F:F, "") -> M21 | Z127: =_xlfn.XLOOKUP(Y127, 'sub-themes'!A:A, 'sub-themes'!H:H, "") -> T2
A128: 120 | B128: 183 | C128: code_comment | D128: 2 | E128: 1 | F128: ['add'] | G128: ['sentence-transformers/multi-qa-mpnet-base-cos-v1'] | H128: =SUBSTITUTE(SUBSTITUTE(SUBSTITUTE(SUBSTITUTE(G128,"[",""),"]",""),"'",""),", ","|") -> sentence-transformers/multi-qa-mpnet-base-cos-v1 | I128: =B128 & "||" & F128 & "||" & H128 -> 183||['add']||sentence-transformers/multi-qa-mpnet-base-cos-v1 | J128: =IF(COUNTIF($I$2:I128, I128)=1, 1, 0) -> 0 | K128: =I128 & "||" & X128 -> 183||['add']||sentence-transformers/multi-qa-mpnet-base-cos-v1||C56 | L128: =IF(COUNTIF($K$2:K128, K128)=1, 1, 0) -> 0 | M128: =I128 & "||" & Y128 -> 183||['add']||sentence-transformers/multi-qa-mpnet-base-cos-v1||M21 | N128: =IF(COUNTIF($M$2:M128, M128)=1, 1, 0) -> 0 | O128: =I128 & "||" & Z128 -> 183||['add']||sentence-transformers/multi-qa-mpnet-base-cos-v1||T2 | P128: =IF(COUNTIF($O$2:O128, O128)=1, 1, 0) -> 0 | Q128: =A128& "||" & X128 -> 120||C56 | R128: =IF(COUNTIF($Q$2:Q128, Q128)=1, 1, 0) -> 1 | S128: =A128& "||" & Y128 -> 120||M21 | T128: =IF(COUNTIF($S$2:S128, S128)=1, 1, 0) -> 1 | U128: =A128& "||" & Z128 -> 120||T2 | V128: =IF(COUNTIF($U$2:U128, U128)=1, 1, 0) -> 1 | W128: Add the embedding model for chatbot | X128: C56 | Y128: =_xlfn.XLOOKUP(X128, codes!A:A, codes!F:F, "") -> M21 | Z128: =_xlfn.XLOOKUP(Y128, 'sub-themes'!A:A, 'sub-themes'!H:H, "") -> T2
A129: 121 | B129: 185 | C129: code_comment | D129: 3 | E129: 1 | F129: ['add'] | G129: ['microsoft/resnet-50'] | H129: =SUBSTITUTE(SUBSTITUTE(SUBSTITUTE(SUBSTITUTE(G129,"[",""),"]",""),"'",""),", ","|") -> microsoft/resnet-50 | I129: =B129 & "||" & F129 & "||" & H129 -> 185||['add']||microsoft/resnet-50 | J129: =IF(COUNTIF($I$2:I129, I129)=1, 1, 0) -> 1 | K129: =I129 & "||" & X129 -> 185||['add']||microsoft/resnet-50||C58 | L129: =IF(COUNTIF($K$2:K129, K129)=1, 1, 0) -> 1 | M129: =I129 & "||" & Y129 -> 185||['add']||microsoft/resnet-50||M18 | N129: =IF(COUNTIF($M$2:M129, M129)=1, 1, 0) -> 1 | O129: =I129 & "||" & Z129 -> 185||['add']||microsoft/resnet-50||T2 | P129: =IF(COUNTIF($O$2:O129, O129)=1, 1, 0) -> 1 | Q129: =A129& "||" & X129 -> 121||C58 | R129: =IF(COUNTIF($Q$2:Q129, Q129)=1, 1, 0) -> 1 | S129: =A129& "||" & Y129 -> 121||M18 | T129: =IF(COUNTIF($S$2:S129, S129)=1, 1, 0) -> 1 | U129: =A129& "||" & Z129 -> 121||T2 | V129: =IF(COUNTIF($U$2:U129, U129)=1, 1, 0) -> 1 | W129: Added resnet model usage to enable image feature extraction. | X129: C58 | Y129: =_xlfn.XLOOKUP(X129, codes!A:A, codes!F:F, "") -> M18 | Z129: =_xlfn.XLOOKUP(Y129, 'sub-themes'!A:A, 'sub-themes'!H:H, "") -> T2
A130: 122 | B130: 191 | C130: commit | D130: 2 | E130: 2 | F130: ['add'] | G130: ['jeeejeee/chatglm3-text2sql-spider', 'jeeejeee/baichuan7b-text2sql-spider'] | H130: =SUBSTITUTE(SUBSTITUTE(SUBSTITUTE(SUBSTITUTE(G130,"[",""),"]",""),"'",""),", ","|") -> jeeejeee/chatglm3-text2sql-spider|jeeejeee/baichuan7b-text2sql-spider | I130: =B130 & "||" & F130 & "||" & H130 -> 191||['add']||jeeejeee/chatglm3-text2sql-spider|jeeejeee/baichuan7b-text2sql-spider | J130: =IF(COUNTIF($I$2:I130, I130)=1, 1, 0) -> 1 | K130: =I130 & "||" & X130 -> 191||['add']||jeeejeee/chatglm3-text2sql-spider|jeeejeee/baichuan7b-text2sql-spider||C39 | L130: =IF(COUNTIF($K$2:K130, K130)=1, 1, 0) -> 1 | M130: =I130 & "||" & Y130 -> 191||['add']||jeeejeee/chatglm3-text2sql-spider|jeeejeee/baichuan7b-text2sql-spider||M26 | N130: =IF(COUNTIF($M$2:M130, M130)=1, 1, 0) -> 1 | O130: =I130 & "||" & Z130 -> 191||['add']||jeeejeee/chatglm3-text2sql-spider|jeeejeee/baichuan7b-text2sql-spider||T1 | P130: =IF(COUNTIF($O$2:O130, O130)=1, 1, 0) -> 1 | Q130: =A130& "||" & X130 -> 122||C39 | R130: =IF(COUNTIF($Q$2:Q130, Q130)=1, 1, 0) -> 1 | S130: =A130& "||" & Y130 -> 122||M26 | T130: =IF(COUNTIF($S$2:S130, S130)=1, 1, 0) -> 1 | U130: =A130& "||" & Z130 -> 122||T1 | V130: =IF(COUNTIF($U$2:U130, U130)=1, 1, 0) -> 1 | W130: Added ChatGLM3 and BaiChuan LoRA adapters to test and enable LoRA-based inference support. for merged-QKV architectures. (LoRa is their functionality) | X130: C39 | Y130: =_xlfn.XLOOKUP(X130, codes!A:A, codes!F:F, "") -> M26 | Z130: =_xlfn.XLOOKUP(Y130, 'sub-themes'!A:A, 'sub-themes'!H:H, "") -> T1
A131: 123 | B131: 191 | C131: pull_request | D131: 2 | E131: 2 | F131: ['add'] | G131: ['jeeejeee/chatglm3-text2sql-spider', 'jeeejeee/baichuan7b-text2sql-spider'] | H131: =SUBSTITUTE(SUBSTITUTE(SUBSTITUTE(SUBSTITUTE(G131,"[",""),"]",""),"'",""),", ","|") -> jeeejeee/chatglm3-text2sql-spider|jeeejeee/baichuan7b-text2sql-spider | I131: =B131 & "||" & F131 & "||" & H131 -> 191||['add']||jeeejeee/chatglm3-text2sql-spider|jeeejeee/baichuan7b-text2sql-spider | J131: =IF(COUNTIF($I$2:I131, I131)=1, 1, 0) -> 0 | K131: =I131 & "||" & X131 -> 191||['add']||jeeejeee/chatglm3-text2sql-spider|jeeejeee/baichuan7b-text2sql-spider||C39 | L131: =IF(COUNTIF($K$2:K131, K131)=1, 1, 0) -> 0 | M131: =I131 & "||" & Y131 -> 191||['add']||jeeejeee/chatglm3-text2sql-spider|jeeejeee/baichuan7b-text2sql-spider||M26 | N131: =IF(COUNTIF($M$2:M131, M131)=1, 1, 0) -> 0 | O131: =I131 & "||" & Z131 -> 191||['add']||jeeejeee/chatglm3-text2sql-spider|jeeejeee/baichuan7b-text2sql-spider||T1 | P131: =IF(COUNTIF($O$2:O131, O131)=1, 1, 0) -> 0 | Q131: =A131& "||" & X131 -> 123||C39 | R131: =IF(COUNTIF($Q$2:Q131, Q131)=1, 1, 0) -> 1 | S131: =A131& "||" & Y131 -> 123||M26 | T131: =IF(COUNTIF($S$2:S131, S131)=1, 1, 0) -> 1 | U131: =A131& "||" & Z131 -> 123||T1 | V131: =IF(COUNTIF($U$2:U131, U131)=1, 1, 0) -> 1 | W131: Enabled LoRA inference for ChatGLM3/BaiChuan by adding new LoRA linear wrappers for merged QKV and projection layers. (LoRa is their functionality) | X131: C39 | Y131: =_xlfn.XLOOKUP(X131, codes!A:A, codes!F:F, "") -> M26 | Z131: =_xlfn.XLOOKUP(Y131, 'sub-themes'!A:A, 'sub-themes'!H:H, "") -> T1
...

Sheet codes
A1: ID | B1: Code | C1: Doc Count | D1: Model Change Count | E1: Frequency | F1: Sub-theme | G1: Add Count | H1: Remove Count | I1: Migrate Count | J1: Doc Count
A2: C1 | B2: Enable model-based jailbreak detection functionality | C2: {=SUMPRODUCT(--('key information'!$X$2:$X$220=$A2), --('key information'!$R$2:$R$220=1))} -> 2 | D2: {=SUMPRODUCT( --('key information'!$X$2:$X$220=$A2), --('key information'!$L$2:$L$220=1), IFERROR(VALUE('key information'!$D$2:$D$220),0) )} -> 2 | E2: =COUNTIF('key information'!X2:X220, codes!A2) -> 2 | F2: M13 | G2: {=SUMPRODUCT( --('key information'!$X$2:$X$220=$A2), --('key information'!$L$2:$L$220=1), --('key information'!$F$2:$F$220="['add']"), IFERROR(VALUE('key information'!$D$2:$D$220),0) )} -> 2 | H2: {=SUMPRODUCT( --('key information'!$X$2:$X$220=$A2), --('key information'!$L$2:$L$220=1), --('key information'!$F$2:$F$220="['remove']"), IFERROR(VALUE('key information'!$D$2:$D$220),0) )} -> 0 | I2: {=SUMPRODUCT( --('key information'!$X$2:$X$220=$A2), --('key information'!$L$2:$L$220=1), --('key information'!$F$2:$F$220="['migrate']"), IFERROR(VALUE('key information'!$D$2:$D$220),0) )} -> 0 | J2: =COUNTIF('key information'!$X:$X, A2) -> 2
A3: C2 | B3: Expand generic feature extraction capabilities | C3: {=SUMPRODUCT(--('key information'!$X$2:$X$220=$A3), --('key information'!$R$2:$R$220=1))} -> 3 | D3: {=SUMPRODUCT( --('key information'!$X$2:$X$220=$A3), --('key information'!$L$2:$L$220=1), IFERROR(VALUE('key information'!$D$2:$D$220),0) )} -> 1 | E3: =COUNTIF('key information'!X3:X221, codes!A3) -> 3 | F3: M18 | G3: {=SUMPRODUCT( --('key information'!$X$2:$X$220=$A3), --('key information'!$L$2:$L$220=1), --('key information'!$F$2:$F$220="['add']"), IFERROR(VALUE('key information'!$D$2:$D$220),0) )} -> 1 | H3: {=SUMPRODUCT( --('key information'!$X$2:$X$220=$A3), --('key information'!$L$2:$L$220=1), --('key information'!$F$2:$F$220="['remove']"), IFERROR(VALUE('key information'!$D$2:$D$220),0) )} -> 0 | I3: {=SUMPRODUCT( --('key information'!$X$2:$X$220=$A3), --('key information'!$L$2:$L$220=1), --('key information'!$F$2:$F$220="['migrate']"), IFERROR(VALUE('key information'!$D$2:$D$220),0) )} -> 0 | J3: =COUNTIF('key information'!$X:$X, A3) -> 3
A4: C3 | B4: Improve named entity recognition functionality | C4: {=SUMPRODUCT(--('key information'!$X$2:$X$220=$A4), --('key information'!$R$2:$R$220=1))} -> 1 | D4: {=SUMPRODUCT( --('key information'!$X$2:$X$220=$A4), --('key information'!$L$2:$L$220=1), IFERROR(VALUE('key information'!$D$2:$D$220),0) )} -> 1 | E4: =COUNTIF('key information'!X4:X222, codes!A4) -> 1 | F4: M19 | G4: {=SUMPRODUCT( --('key information'!$X$2:$X$220=$A4), --('key information'!$L$2:$L$220=1), --('key information'!$F$2:$F$220="['add']"), IFERROR(VALUE('key information'!$D$2:$D$220),0) )} -> 1 | H4: {=SUMPRODUCT( --('key information'!$X$2:$X$220=$A4), --('key information'!$L$2:$L$220=1), --('key information'!$F$2:$F$220="['remove']"), IFERROR(VALUE('key information'!$D$2:$D$220),0) )} -> 0 | I4: {=SUMPRODUCT( --('key information'!$X$2:$X$220=$A4), --('key information'!$L$2:$L$220=1), --('key information'!$F$2:$F$220="['migrate']"), IFERROR(VALUE('key information'!$D$2:$D$220),0) )} -> 0 | J4: =COUNTIF('key information'!$X:$X, A4) -> 1
